<?xml version="1.0"?>
<robot name="xarm_gripper">
  <link name="xarm_gripper_base_link">
    <visual>
      <origin xyz="0 0 0" rpy="0 0 0"/>
      <geometry>
        <mesh filename="meshes/base_link.stl"/>
      </geometry>
    </visual>
    <collision>
      <origin xyz="0 0 0" rpy="0 0 0"/>
      <geometry>
        <mesh filename="meshes/base_link.stl"/>
      </geometry>
    </collision>
  </link>

  <link name="left_outer_knuckle">
    <visual>
      <origin xyz="0 0 0" rpy="0 0 0"/>
      <geometry>
        <mesh filename="meshes/left_outer_knuckle.stl"/>
      </geometry>
    </visual>
    <collision>
      <origin xyz="0 0 0" rpy="0 0 0"/>
      <geometry>
        <mesh filename="meshes/left_outer_knuckle.stl"/>
      </geometry>
    </collision>
  </link>

  <joint name="drive_joint" type="revolute">
    <origin xyz="0 0.035 0.059098" rpy="0 0 0"/>
    <parent link="xarm_gripper_base_link"/>
    <child link="left_outer_knuckle"/>
    <axis xyz="1 0 0"/>
    <limit lower="0" upper="0.85" effort="50" velocity="2"/>
  </joint>

  <link name="left_finger">
    <visual>
      <origin xyz="0 0 0" rpy="0 0 0"/>
      <geometry>
        <mesh filename="meshes/left_finger.stl"/>
      </geometry>
    </visual>
    <collision>
      <origin xyz="0 0 0" rpy="0 0 0"/>
      <geometry>
        <mesh filename="meshes/left_finger.stl"/>
      </geometry>
    </collision>
  </link>

  <joint name="left_finger_joint" type="revolute">
    <origin xyz="0 0.035465 0.042039" rpy="0 0 0"/>
    <parent link="left_outer_knuckle"/>
    <child link="left_finger"/>
    <axis xyz="-1 0 0"/>
    <limit lower="0" upper="0.85" effort="50" velocity="2"/>
    <mimic joint="drive_joint" multiplier="1" offset="0"/>
  </joint>

  <link name="left_inner_knuckle">
    <visual>
      <origin xyz="0 0 0" rpy="0 0 0"/>
      <geometry>
        <mesh filename="meshes/left_inner_knuckle.stl"/>
      </geometry>
    </visual>
    <collision>
      <origin xyz="0 0 0" rpy="0 0 0"/>
      <geometry>
        <mesh filename="meshes/left_inner_knuckle.stl"/>
      </geometry>
    </collision>
  </link>

  <joint name="left_inner_knuckle_joint" type="revolute">
    <origin xyz="0 0.02 0.074098" rpy="0 0 0"/>
    <parent link="xarm_gripper_base_link"/>
    <child link="left_inner_knuckle"/>
    <axis xyz="1 0 0"/>
    <limit lower="0" upper="0.85" effort="50" velocity="2"/>
    <mimic joint="drive_joint" multiplier="1" offset="0"/>
  </joint>

  <link name="right_outer_knuckle">
    <visual>
      <origin xyz="0 0 0" rpy="0 0 0"/>
      <geometry>
        <mesh filename="meshes/right_outer_knuckle.stl"/>
      </geometry>
    </visual>
    <collision>
      <origin xyz="0 0 0" rpy="0 0 0"/>
      <geometry>
        <mesh filename="meshes/right_outer_knuckle.stl"/>
      </geometry>
    </collision>
  </link>

  <joint name="right_outer_knuckle_joint" type="revolute">
    <origin xyz="0 -0.035 0.059098" rpy="0 0 0"/>
    <parent link="xarm_gripper_base_link"/>
    <child link="right_outer_knuckle"/>
    <axis xyz="-1 0 0"/>
    <limit lower="0" upper="0.85" effort="50" velocity="2"/>
    <mimic joint="drive_joint" multiplier="1" offset="0"/>
  </joint>

  <link name="right_finger">
    <visual>
      <origin xyz="0 0 0" rpy="0 0 0"/>
      <geometry>
        <mesh filename="meshes/right_finger.stl"/>
      </geometry>
    </visual>
    <collision>
      <origin xyz="0 0 0" rpy="0 0 0"/>
      <geometry>
        <mesh filename="meshes/right_finger.stl"/>
      </geometry>
    </collision>
  </link>

  <joint name="right_finger_joint" type="revolute">
    <origin xyz="0 -0.035465 0.042039" rpy="0 0 0"/>
    <parent link="right_outer_knuckle"/>
    <child link="right_finger"/>
    <axis xyz="1 0 0"/>
    <limit lower="0" upper="0.85" effort="50" velocity="2"/>
    <mimic joint="drive_joint" multiplier="1" offset="0"/>
  </joint>

  <link name="right_inner_knuckle">
    <visual>
      <origin xyz="0 0 0" rpy="0 0 0"/>
      <geometry>
        <mesh filename="meshes/right_inner_knuckle.stl"/>
      </geometry>
    </visual>
    <collision>
      <origin xyz="0 0 0" rpy="0 0 0"/>
      <geometry>
        <mesh filename="meshes/right_inner_knuckle.stl"/>
      </geometry>
    </collision>
  </link>

  <joint name="right_inner_knuckle_joint" type="revolute">
    <origin xyz="0 -0.02 0.074098" rpy="0 0 0"/>
    <parent link="xarm_gripper_base_link"/>
    <child link="right_inner_knuckle"/>
    <axis xyz="-1 0 0"/>
    <limit lower="0" upper="0.85" effort="50" velocity="2"/>
    <mimic joint="drive_joint" multiplier="1" offset="0"/>
  </joint>

  <link name="link_tcp"/>
  <joint name="joint_tcp" type="fixed">
    <origin xyz="0 0 0.172" rpy="0 0 0"/>
    <parent link="xarm_gripper_base_link"/>
    <child link="link_tcp"/>
  </joint>
</robot>
